Workbook

Sheet MMPS
A1: versionid | B1: versionname | C1: tablename | D1: sequence | E1: elementname | F1: turnaroundind | G1: sampledata | H1: exportind | I1: elementid | J1: parentelementid | K1: parentelementid | L1: relationshiptype | M1: elementtype | N1: fieldname | O1: columnname | P1: languagecode | Q1: ddetype | R1: countrydesc | S1: countrycode | T1: regioncode | U1: elementlength | V1: elementprecision | W1: collectionunits | X1: guidelines | Y1: csfieldname | Z1: colusage | AA1: ascentnullableind | AB1: nullableind | AC1: note | AD1: fieldname | AE1: elementname | AF1: elementdesc | AG1: guidelines | AH1: sampledata | AI1: excelformula | AJ1: expression | AK1: loadrule
A2: A24261921654 | B2: 2025 MMPS Template | C2: SUBMISSIONINCUMBENT | D2: 1 | E2: Country Code | F2: Y | G2: ~NA:USA~DEFAULT:GBR~APAC:JPN~LATAM:BRA~CHINA:CHN~EDUCATION:MYS | H2: Y | I2: 14 | J2: NULL | K2: NULL | L2: NULL | M2: CHAR | N2: COUNTRYCODE | O2: COUNTRYCODE | P2: USE | Q2: L | R2: United States | S2: USA | T2: USA | U2: 5 | V2: 0 | W2: W | X2: Refer to the Country Codes tab. | Y2: NULL | Z2: M | AA2: N | AB2: N | AC2: INT:~CORE~CYCAR~ | AD2: COUNTRYCODE | AE2: Country Code | AF2: The country code of the primary office to which they are assigned. | AG2: Refer to the Country Codes tab. | AH2: ~NA:USA~DEFAULT:GBR~APAC:JPN~LATAM:BRA~CHINA:CHN~EDUCATION:MYS | AI2: NULL | AK2: If(:COUNTRYCODE="xx",null,Trim(Upper(:COUNTRYCODE)))
A3: A24261921654 | B3: 2025 MMPS Template | C3: SUBMISSIONUNIT | D3: 1 | E3: New Hire [Calculated] | F3: N | G3: NULL | H3: N | I3: NULL | J3: NULL | K3: NULL | L3: NULL | M3: BOOL | N3: SCOPE_UNIT | O3: NULL | P3: USE | Q3: C | R3: United States | S3: USA | T3: USA | U3: 12 | V3: 0 | W3: W | X3: NULL | Y3: NULL | Z3: NULL | AA3: Y | AB3: Y | AC3: ~XXX~ | AD3: SCOPE_UNIT | AE3: New Hire [Calculated] | AF3: The incumbent was hired on or after 1 January of the previous year. | AG3: NULL | AH3: NULL | AI3: NULL | AJ3: if(isnull( :FD_DOH_DAT),null,if(Number(FormatDate(:FD_DOH_DAT,"YYYY")) >= 2021, "Y", "N")) | AK3: NULL
A4: A24261921654 | B4: 2025 MMPS Template | C4: SUBMISSIONCONTACT | D4: 1 | E4: Report Recipient Name | F4: N | G4: Ms. Jan Doe | H4: Y | I4: 990 | J4: NULL | K4: NULL | L4: NULL | M4: CHAR | N4: CONTACT_NAME | O4: DDE034 | P4: USE | Q4: L | R4: United States | S4: USA | T4: USA | U4: 250 | V4: 0 | W4: W | Y4: NULL | Z4: M | AA4: Y | AB4: Y | AC4: ~CORE_NA~AERO_NA~ | AD4: CONTACT_NAME | AE4: Report Recipient Name | AF4: Report Recipient Name | AH4: Ms. Jan Doe | AI4: NULL | AK4: NULL
A5: A24261921654 | B5: 2025 MMPS Template | C5: SUBMISSIONGRANT | D5: 1 | E5: Case Number | F5: N | G5: NULL | H5: N | I5: 22 | J5: NULL | K5: NULL | L5: NULL | M5: CHAR | N5: CASEID | O5: CASEID | P5: USE | Q5: L | R5: United States | S5: USA | T5: USA | U5: 7 | V5: 0 | W5: W | X5: NULL | Y5: NULL | Z5: M | AA5: N | AB5: N | AC5: ADV,DSW:~CORE~;HID:~MFG_LATAM~CYCAR~ | AD5: CASEID | AE5: Case Number | AF5: Seven-digit case number to uniquely identify each incumbent. | AG5: NULL | AH5: NULL | AI5: NULL | AK5: If(:CASEID="XXXX",null,LPad(:CASEID,6,"0"))
A6: A24261921654 | B6: 2025 MMPS Template | C6: SUBMISSIONCOMPANY | D6: 1 | E6: Participating Entity Name | F6: N | G6: ~CSR:ABC Subsidiary~DEFAULT:Your Company Name~ | H6: Y | I6: 566 | J6: NULL | K6: NULL | L6: NULL | M6: CHAR | N6: COMPANY_NAME | O6: DDE038 | P6: USE | Q6: L | R6: United States | S6: USA | T6: USA | U6: 255 | V6: 0 | W6: W | X6: NULL | Y6: NULL | Z6: M | AA6: Y | AB6: Y | AC6: ~CORE~CYCAR~ | AD6: COMPANY_NAME | AE6: Participating Entity Name | AF6: The name of your organization. | AG6: NULL | AH6: ~CSR:ABC Subsidiary~DEFAULT:Your Company Name~ | AI6: NULL | AK6: NULL
A7: A24261921654 | B7: 2025 MMPS Template | C7: SUBMISSIONGRANT | D7: 2 | E7: Long-Term Incentive Plan Type | F7: N | G7: PP | H7: Y | I7: 83 | J7: NULL | K7: NULL | L7: NULL | M7: PICK | N7: PLANTYPE | O7: PLANTYPE | P7: USE | Q7: L | R7: United States | S7: USA | T7: USA | U7: 5 | V7: 0 | W7: W | X7: PP-Performance Plan Awards: Performance Plan Awards are contingent grants of cash or stock that are earned in whole or in part according to the degree of achievement of performance goals over a defined period (usually three years). In EMEA, some grants can be contingent upon bonus deferral (deferred bonus matching plans) or the purchase of company stock (co-investment plans). RS-Restricted Stock/Stock Units: Restricted Stock/Stock Units are grants of stock or stock units at no or nominal cost. The restrictions and risk of forfeiture lapse with continued employment over a period of years. If vesting also includes a performance condition, such condition is considered to be nominal with a high likelihood of being attained. Dividends or dividend equivalents may be paid or accrued during the restricted period. SO-Stock Options/SARs: Stock Options are rights to purchase a fixed number of shares of a company's stock, at a stated price for a specified period of time. Stock Appreciation Rights (SARs) are rights to receive payment equal in value to the appreciation on a share of stock between the date on which the SAR was granted and the date on which the employee exercises his/her appreciation rights. | Y7: NULL | Z7: M | AA7: Y | AB7: Y | AC7: INT:~CORE~ | AD7: PLANTYPE | AE7: Long-Term Incentive Plan Type | AF7: Type of long-term grant data being reported. | AG7: PP-Performance Plan Awards: Performance Plan Awards are contingent grants of cash or stock that are earned in whole or in part according to the degree of achievement of performance goals over a defined period (usually three years). In EMEA, some grants can be contingent upon bonus deferral (deferred bonus matching plans) or the purchase of company stock (co-investment plans). RS-Restricted Stock/Stock Units: Restricted Stock/Stock Units are grants of stock or stock units at no or nominal cost. The restrictions and risk of forfeiture lapse with continued employment over a period of years. If vesting also includes a performance condition, such condition is considered to be nominal with a high likelihood of being attained. Dividends or dividend equivalents may be paid or accrued during the restricted period. SO-Stock Options/SARs: Stock Options are rights to purchase a fixed number of shares of a company's stock, at a stated price for a specified period of time. Stock Appreciation Rights (SARs) are rights to receive payment equal in value to the appreciation on a share of stock between the date on which the SAR was granted and the date on which the employee exercises his/her appreciation rights. | AH7: PP | AI7: NULL | AK7: UPPER(TRIM(:PLANTYPE))
A8: A24261921654 | B8: 2025 MMPS Template | C8: SUBMISSIONCOMPANY | D8: 2 | E8: Participating Entity Country | F8: Y | G8: ~NA:USA [United States]~DEFAULT:GBR [United Kingdom]~APAC:JPN [Japan]~LATAM:BRA [Brazil]~CHINA:CHN [China]~EDUCATION:MYS [Malaysia]~ | H8: Y | I8: 35000 | J8: NULL | K8: NULL | L8: NULL | M8: PICK | N8: ISO3 | O8: DDE207 | P8: USE | Q8: L | R8: United States | S8: USA | T8: USA | U8: 5 | V8: 0 | W8: W | X8: Refer to the Country Codes tab. | Y8: NULL | Z8: M | AA8: N | AB8: Y | AC8: DSW:~CORE~CYCAR~ | AD8: ISO3 | AE8: Participating Entity Country | AF8: The country where the participating entity is based/headquartered. | AG8: Refer to the Country Codes tab. | AH8: ~NA:USA [United States]~DEFAULT:GBR [United Kingdom]~APAC:JPN [Japan]~LATAM:BRA [Brazil]~CHINA:CHN [China]~EDUCATION:MYS [Malaysia]~ | AI8: NULL | AK8: NULL
A9: A24261921654 | B9: 2025 MMPS Template | C9: SUBMISSIONINCUMBENT | D9: 2 | E9: Country Code (PHRA) | F9: Y | G9: USA | H9: Y | I9: 78097 | J9: NULL | K9: NULL | L9: NULL | M9: PICK | N9: COUNTRY_PHE | O9: DDE641 | P9: USE | Q9: L | R9: United States | S9: USA | T9: USA | U9: 5 | V9: 0 | W9: W | X9: Refer to the Country Codes tab. NOTE: As agreed by the PHRA, all top 30 highest paid EX level incumbents should be included regardless of country or pay currency. | Y9: NULL | Z9: S | AA9: N | AB9: Y | AC9: ~PHRA_NA~ | AD9: COUNTRY_PHE | AE9: Country Code (PHRA) | AF9: For PHRA, the country code of the primary office to which they are assigned. | AG9: Refer to the Country Codes tab. NOTE: As agreed by the PHRA, all top 30 highest paid EX level incumbents should be included regardless of country or pay currency. | AH9: USA | AI9: NULL | AK9: NULL
A10: A24261921654 | B10: 2025 MMPS Template | C10: SUBMISSIONUNIT | D10: 2 | E10: Unit Number | F10: Y | G10: 1 | H10: N | I10: 10 | J10: NULL | K10: NULL | L10: NULL | M10: CHAR | N10: UNITNUM | O10: UNITNUM | P10: USE | Q10: L | R10: United States | S10: USA | T10: USA | U10: 12 | V10: 0 | W10: W | X10: Enter a unique three-digit code (e.g., 001, 002) to identify each unit. Unit numbers will be assigned to the corresponding incumbent in these units in the Incumbent Data worksheet. | Y10: NULL | Z10: M | AA10: N | AB10: N | AC10: ~CORE~AERO_NA~SSO~RCE~AGRO_ZAF~MDSUK~YOUNGGRAD~RENEWABLE~RENEWCLUB_FRA~AERO_EMEA~AERO_BRA~HC_GCC~HC_APAC~HIGHER_EDU~CMPIF_CHN~EDU_APAC~UPSTREAM_MYS~LEGAL_FEE_EARNERS~CL_PS_SUPPORTSTAFF_INTL~CL_HRG~CYCAR~ | AD10: UNITNUM | AE10: Unit Number | AF10: The unit number for the incumbent's unit. | AG10: Enter a unique three-digit code (e.g., 001, 002) to identify each unit. Unit numbers will be assigned to the corresponding incumbent in these units in the Incumbent Data worksheet. | AH10: 1 | AI10: NULL | AK10: NULL
A11: A24261921654 | B11: 2025 MMPS Template | C11: SUBMISSIONCONTACT | D11: 2 | E11: Report Recipient Title | F11: N | G11: Compensation Analyst | H11: Y | I11: 991 | J11: NULL | K11: NULL | L11: NULL | M11: CHAR | N11: CONTACT_TITLE | O11: DDE035 | P11: USE | Q11: L | R11: United States | S11: USA | T11: USA | U11: 250 | V11: 0 | W11: W | Y11: NULL | Z11: M | AA11: Y | AB11: Y | AC11: ~CORE_NA~AERO_NA~ | AD11: CONTACT_TITLE | AE11: Report Recipient Title | AF11: Report Recipient Title | AH11: Compensation Analyst | AI11: NULL | AK11: NULL
A12: A24261921654 | B12: 2025 MMPS Template | C12: SUBMISSIONUNIT | D12: 3 | E12: 2020 Radio Rank | F12: Y | G12: NULL | H12: Y | I12: 1081 | J12: NULL | K12: NULL | L12: NULL | M12: PICK | N12: NEXT_YEAR_RADIO_RANK | O12: DDE028 | P12: USE | Q12: L | R12: United States | S12: USA | T12: USA | U12: 5 | V12: 0 | W12: W | X12: NULL | Y12: NULL | Z12: S | AA12: Y | AB12: Y | AC12: ~XXX~ | AD12: NEXT_YEAR_RADIO_RANK | AE12: 2020 Radio Rank | AF12: The appropriate radio market rank for each station. | AG12: NULL | AH12: NULL | AI12: NULL | AJ12: NULL | AK12: NULL
A13: A24261921654 | B13: 2025 MMPS Template | C13: SUBMISSIONCONTACT | D13: 3 | E13: Report Recipient Address 1 | F13: N | G13: 100 Park Ave | H13: Y | I13: 992 | J13: NULL | K13: NULL | L13: NULL | M13: CHAR | N13: CONTACT_ADDRESS_1 | O13: DDE036 | P13: USE | Q13: L | R13: United States | S13: USA | T13: USA | U13: 250 | V13: 0 | W13: W | Y13: NULL | Z13: M | AA13: Y | AB13: Y | AC13: ~CORE_NA~AERO_NA~ | AD13: CONTACT_ADDRESS_1 | AE13: Report Recipient Address 1 | AF13: Report Recipient Address 1 | AH13: 100 Park Ave | AI13: NULL | AK13: NULL
A14: A24261921654 | B14: 2025 MMPS Template | C14: SUBMISSIONCOMPANY | D14: 3 | E14: Participating Entity Structure | F14: Y | G14: ~CSR:3~DEFAULT:1 [Public Parent]~ | H14: Y | I14: 3162 | J14: NULL | K14: NULL | L14: NULL | M14: PICK | N14: CRP_STRUCTURE | O14: DDE127 | P14: USE | Q14: L | R14: United States | S14: USA | T14: USA | U14: 5 | V14: 0 | W14: W | X14: 1-Public Parent 2-Private Parent 3-Wholly Owned Subsidiary 4-Publicly Traded Subsidiary 5-Not-for-Profit 6-Government Agency 7-Joint Venture 8-Mutual Company | Y14: NULL | Z14: M | AA14: Y | AB14: Y | AC14: ADV:~CORE_EXEC~CORE_NONEXEC_NA;INT:~CORE_NONEXEC_EMEA~CORE_NONEXEC_LATAM~CORE_NONEXEC_APAC~CYCAR~ | AD14: CRP_STRUCTURE | AE14: Participating Entity Structure | AF14: Corporate structure of the participating entity. | AG14: 1-Public Parent 2-Private Parent 3-Wholly Owned Subsidiary 4-Publicly Traded Subsidiary 5-Not-for-Profit 6-Government Agency 7-Joint Venture 8-Mutual Company | AH14: ~CSR:3~DEFAULT:1 [Public Parent]~ | AI14: NULL | AK14: NULL
A15: A24261921654 | B15: 2025 MMPS Template | C15: SUBMISSIONINCUMBENT | D15: 3 | E15: Case Number | F15: Y | G15: 1 | H15: Y | I15: 12 | J15: NULL | K15: NULL | L15: NULL | M15: CHAR | N15: CASEID | O15: CASEID | P15: USE | Q15: L | R15: United States | S15: USA | T15: USA | U15: 7 | V15: 0 | W15: W | X15: Number the cases starting with 0000001. | Y15: NULL | Z15: M | AA15: N | AB15: N | AC15: ADV,DSW:~CORE~;HID:~MFG_LATAM~ | AD15: CASEID | AE15: Case Number | AF15: Seven-digit case number to uniquely identify each incumbent. | AG15: Number the cases starting with 0000001. | AH15: 1 | AI15: NULL | AK15: If(:CASEID="XXXX",null,LPad(:CASEID,6,"0"))
A16: A24261921654 | B16: 2025 MMPS Template | C16: SUBMISSIONGRANT | D16: 3 | E16: Long-Term Incentive Plan Number | F16: N | G16: PP01 | H16: Y | I16: 23 | J16: NULL | K16: NULL | L16: NULL | M16: CHAR | N16: PLANCODE | O16: PLANCODE | P16: USE | Q16: L | R16: United States | S16: USA | T16: USA | U16: 12 | V16: 0 | W16: W | X16: If under the same plan different incumbents have different vesting arrangements, report each plan separately. For example, if a performance cash plan has a TSR performance condition applicable to board member and an EPS performance condition applicable to all other incumbents, code each as a separate plan. | Y16: NULL | Z16: M | AA16: Y | AB16: Y | AC16: DSW,INT:~CORE~;HID:~MFG_LATAM~CYCAR~ | AD16: PLANCODE | AE16: Long-Term Incentive Plan Number | AF16: The plan number is located on each plan type worksheet on the data submission spreadsheet and is required for each grant. The Long-Term Plan Number (e.g., PP01) ties the shares granted with the plan data. | AG16: If under the same plan different incumbents have different vesting arrangements, report each plan separately. For example, if a performance cash plan has a TSR performance condition applicable to board member and an EPS performance condition applicable to all other incumbents, code each as a separate plan. | AH16: PP01 | AI16: NULL | AK16: TRIM(UPPER(:PLANCODE))
A17: A24261921654 | B17: 2025 MMPS Template | C17: SUBMISSIONCONTACT | D17: 4 | E17: Report Recipient Address 2 | F17: N | G17: 9th Floor | H17: Y | I17: 993 | J17: NULL | K17: NULL | L17: NULL | M17: CHAR | N17: CONTACT_ADDRESS_2 | O17: DDE037 | P17: USE | Q17: L | R17: United States | S17: USA | T17: USA | U17: 250 | V17: 0 | W17: W | Y17: NULL | Z17: M | AA17: Y | AB17: Y | AC17: ~CORE_NA~AERO_NA~ | AD17: CONTACT_ADDRESS_2 | AE17: Report Recipient Address 2 | AF17: Report Recipient Address 2 | AH17: 9th Floor | AI17: NULL | AK17: NULL
A18: A24261921654 | B18: 2025 MMPS Template | C18: SUBMISSIONCOMPANY | D18: 4 | E18: Type of Ownership | F18: N | G18: NULL | H18: Y | I18: 1291 | J18: NULL | K18: NULL | L18: NULL | M18: PICK | N18: TYPE_OWNERSHIP | O18: DDE110 | P18: USE | Q18: L | R18: United States | S18: USA | T18: USA | U18: 5 | V18: 0 | W18: W | X18: NULL | Y18: NULL | Z18: S | AA18: NULL | AB18: Y | AC18: ~XXX~ | AD18: TYPE_OWNERSHIP | AE18: Type of Ownership | AF18: Indicate if your company ownership is stock or mutual. | AG18: NULL | AH18: NULL | AI18: NULL | AJ18: NULL | AK18: NULL
A19: A24261921654 | B19: 2025 MMPS Template | C19: SUBMISSIONGRANT | D19: 4 | E19: Grant Date | F19: N | G19: ~NA:4/15/2024~APAC,EMEA,LATAM:3/1/2023~ | H19: Y | I19: 196 | J19: NULL | K19: NULL | L19: NULL | M19: DATE | N19: GRANT_DATE | O19: DDE001 | P19: USE | Q19: L | R19: United States | S19: USA | T19: USA | U19: 8 | V19: 0 | W19: W | X19: Provide date of grants in the last 12 months. Enter the date in your normal date format (DD/MM/YY or MM/DD/YY depending on user default). For special grants provided in lieu of annual grants and for multi-year or mega grants, please enter your most recent grant which could be more than 12 months ago. | Y19: NULL | Z19: M | AA19: Y | AB19: Y | AC19: DSW,INT:~CORE~AERO_NA~SSO~RCE~AGRO_ZAF~MDSUK~RENEWABLE~RENEWCLUB_FRA~AERO_EMEA~AERO_BRA~HC_GCC~HC_APAC~HIGHER_EDU~CMPIF_CHN~EDU_APAC~UPSTREAM_MYS~DRILL_GLOBAL~DRILL_NAT~CL_PS_SUPPORTSTAFF_INTL~CL_HRG~;HID:~MFG_LATAM~CYCAR~ | AD19: GRANT_DATE | AE19: Grant Date | AF19: Date the grant was made. | AG19: Provide date of grants in the last 12 months. Enter the date in your normal date format (DD/MM/YY or MM/DD/YY depending on user default). For special grants provided in lieu of annual grants and for multi-year or mega grants, please enter your most recent grant which could be more than 12 months ago. | AH19: ~NA:4/15/2024~APAC,EMEA,LATAM:3/1/2023~ | AI19: NULL | AK19: NULL
A20: A24261921654 | B20: 2025 MMPS Template | C20: SUBMISSIONINCUMBENT | D20: 4 | E20: Reports to Case Number | F20: Y | G20: 1 | H20: Y | I20: 20 | J20: NULL | K20: NULL | L20: NULL | M20: CHAR | N20: SUPERVISORCASEID | O20: SUPERVISORCASEID | P20: USE | Q20: L | R20: United States | S20: USA | T20: USA | U20: 7 | V20: 0 | W20: W | X20: This should only be provided for jobs matched to the EX career band. | Y20: NULL | Z20: M | AA20: Y | AB20: Y | AC20: ADV:~CORE_EXEC~CORE_EXEC_NA~MDSUK~AERO_EMEA~AERO_BRA~CL_HRG~;DSW,INT:~CORE_NONEXEC~RENEWABLE~HIGHER_EDU~ | AD20: SUPERVISORCASEID | AE20: Reports to Case Number | AF20: Seven-digit case number of the executive to whom the incumbent reports. If that executive is not matched to this survey, leave this field blank. | AG20: This should only be provided for jobs matched to the EX career band. | AH20: 1 | AI20: NULL | AK20: If(IsNull(:SUPERVISORCASEID),Null,LPad(:SUPERVISORCASEID,6,"0"))
A21: A24261921654 | B21: 2025 MMPS Template | C21: SUBMISSIONUNIT | D21: 4 | E21: Business Unit Name | F21: Y | G21: ~CSR:Widget Division~HCNA:XYZ Corp~DEFAULT:EXAMPLE LOB~ | H21: Y | I21: 408 | J21: NULL | K21: NULL | L21: NULL | M21: CHAR | N21: L_O_B | O21: DDE010 | P21: USE | Q21: L | R21: United States | S21: USA | T21: USA | U21: 250 | V21: 0 | W21: W | X21: If the parent organization employees are included in the data submission, one of the units should be named "parent" or "corporate" for reporting incumbents with organizationwide responsibility. | Y21: NULL | Z21: M | AA21: Y | AB21: Y | AC21: ~XXX~ | AD21: L_O_B | AE21: Business Unit Name | AF21: Name of the unit for which data is reported. | AG21: If the parent organization employees are included in the data submission, one of the units should be named "parent" or "corporate" for reporting incumbents with organizationwide responsibility. | AH21: ~CSR:Widget Division~HCNA:XYZ Corp~DEFAULT:EXAMPLE LOB~ | AI21: NULL | AJ21: NULL | AK21: NULL
A22: A24261921654 | B22: 2025 MMPS Template | C22: SUBMISSIONUNIT | D22: 5 | E22: Postal/ZIP Code | F22: Y | G22: NULL | H22: Y | I22: 1074 | J22: NULL | K22: NULL | L22: NULL | M22: CHAR | N22: POSTZIPCODE | O22: DDE021 | P22: USE | Q22: L | R22: United States | S22: USA | T22: USA | U22: 12 | V22: 0 | W22: W | X22: NULL | Y22: NULL | Z22: S | AA22: Y | AB22: Y | AC22: ~XXX~ | AD22: POSTZIPCODE | AE22: Postal/ZIP Code | AF22: The Postal/ZIP code for the business unit being reported. | AG22: NULL | AH22: NULL | AI22: NULL | AJ22: NULL | AK22: NULL
A23: A24261921654 | B23: 2025 MMPS Template | C23: SUBMISSIONINCUMBENT | D23: 5 | E23: Reports to Title | F23: N | G23: NULL | H23: Y | I23: 5523 | J23: NULL | K23: NULL | L23: NULL | M23: CHAR | N23: RPT2TITLE | O23: DDE212 | P23: USE | Q23: L | R23: United States | S23: USA | T23: USA | U23: 255 | V23: 0 | W23: W | X23: NULL | Y23: NULL | Z23: M | AA23: Y | AB23: Y | AC23: ~XXX~ | AD23: RPT2TITLE | AE23: Reports to Title | AF23: 5523 | AG23: NULL | AH23: NULL | AI23: NULL | AJ23: NULL | AK23: NULL
A24: A24261921654 | B24: 2025 MMPS Template | C24: SUBMISSIONCONTACT | D24: 5 | E24: Report Recipient City | F24: N | G24: New York | H24: Y | I24: 994 | J24: NULL | K24: NULL | L24: NULL | M24: CHAR | N24: CONTACT_CITY | O24: DDE038 | P24: USE | Q24: L | R24: United States | S24: USA | T24: USA | U24: 250 | V24: 0 | W24: W | Y24: NULL | Z24: M | AA24: Y | AB24: Y | AC24: ~CORE_NA~AERO_NA~ | AD24: CONTACT_CITY | AE24: Report Recipient City | AF24: Report Recipient City | AH24: New York | AI24: NULL | AK24: NULL
A25: A24261921654 | B25: 2025 MMPS Template | C25: SUBMISSIONCOMPANY | D25: 5 | E25: Organization Classification | F25: Y | G25: 1 | H25: Y | I25: 34999 | J25: NULL | K25: NULL | L25: NULL | M25: PICK | N25: ORG_TYPE | O25: DDE206 | P25: USE | Q25: L | R25: United States | S25: USA | T25: USA | U25: 5 | V25: 0 | W25: W | X25: 1. Hospital System/Network 2. Non Hospital Organization 3. Independent Hospital/Facility 4. Subsidiary 5. Children's Hospital/Facility | Y25: NULL | Z25: M | AA25: Y | AB25: Y | AC25: ADV:~HC~ | AD25: ORG_TYPE | AE25: Organization Classification | AF25: Select the Organization Classification that best describes your organization. | AG25: 1. Hospital System/Network 2. Non Hospital Organization 3. Independent Hospital/Facility 4. Subsidiary 5. Children's Hospital/Facility | AH25: 1 | AI25: NULL | AK25: NULL
A26: A24261921654 | B26: 2025 MMPS Template | C26: SUBMISSIONGRANT | D26: 5 | E26: Grant Price Currency | F26: N | G26: ~ | H26: Y | I26: 49 | J26: 48 | K26: 48 | L26: C | M26: CHAR | N26: GRANTPRICECURR | O26: GRANTPRICECURR | P26: USE | Q26: L | R26: United States | S26: USA | T26: USA | U26: 15 | V26: 0 | W26: W | X26: Enter the currency for the grant price reported. For example, enter USD for U.S. Dollars, CAD for Canadian Dollars, EUR for Euros, CHF for Swiss Francs and GBP for Pounds Sterling. For performance cash plans this is the currency in which the cash award is expressed. | Y26: NULL | Z26: M | AA26: Y | AB26: Y | AC26: ~CORE~AERO_NA~SSO~RCE~AGRO_ZAF~MDSUK~RENEWABLE~RENEWCLUB_FRA~AERO_EMEA~AERO_BRA~HC_GCC~HC_APAC~HIGHER_EDU~CMPIF_CHN~EDU_APAC~UPSTREAM_MYS~DRILL_GLOBAL~DRILL_NAT~CL_PS_SUPPORTSTAFF_INTL~CL_HRG~;HID:~MFG_LATAM~ | AD26: GRANTPRICECURR | AE26: Grant Price Currency | AF26: The currency code for the grant. | AG26: Enter the currency for the grant price reported. For example, enter USD for U.S. Dollars, CAD for Canadian Dollars, EUR for Euros, CHF for Swiss Francs and GBP for Pounds Sterling. For performance cash plans this is the currency in which the cash award is expressed. | AH26: ~ | AI26: NULL | AK26: Trim(Upper(:GRANTPRICECURR))
A27: A24261921654 | B27: 2025 MMPS Template | C27: SUBMISSIONCOMPANY | D27: 6 | E27: Home Country Executives | F27: Y | G27: 75 | H27: Y | I27: 3165 | J27: NULL | K27: NULL | L27: NULL | M27: NUM | N27: HOME_EXECS | O27: DDE130 | P27: USE | Q27: L | R27: United States | S27: USA | T27: USA | U27: 8 | V27: 0 | W27: W | X27: NULL | Y27: NULL | Z27: M | AA27: Y | AB27: Y | AC27: ~XXX~ | AD27: HOME_EXECS | AE27: Home Country Executives | AF27: The total number of employees designated as executives in the home country. | AG27: NULL | AH27: 75 | AI27: NULL | AK27: NULL
A28: A24261921654 | B28: 2025 MMPS Template | C28: SUBMISSIONCONTACT | D28: 6 | E28: Report Recipient State/Province | F28: N | G28: NY | H28: Y | I28: 995 | J28: NULL | K28: NULL | L28: NULL | M28: CHAR | N28: CONTACT_STATE | O28: DDE039 | P28: USE | Q28: L | R28: United States | S28: USA | T28: USA | U28: 250 | V28: 0 | W28: W | Y28: NULL | Z28: M | AA28: Y | AB28: Y | AC28: ~CORE_NA~AERO_NA~ | AD28: CONTACT_STATE | AE28: Report Recipient State/Province | AF28: Report Recipient State/Province | AH28: NY | AI28: NULL | AK28: NULL
A29: A24261921654 | B29: 2025 MMPS Template | C29: SUBMISSIONGRANT | D29: 6 | E29: Grant Price Per Share/Unit | F29: N | G29: 50 | H29: Y | I29: 48 | J29: NULL | K29: NULL | L29: NULL | M29: MON | N29: GRANTPRICE | O29: GRANTPRICE | P29: USE | Q29: L | R29: United States | S29: USA | T29: USA | U29: 10 | V29: 2 | W29: W | X29: Round all prices to two decimal places (e.g., 12.125 should be entered as 12.13). If you are reporting a performance cash plan, co-investment shares and/or deferred bonus matching shares enter 1.00. | Y29: NULL | Z29: M | AA29: Y | AB29: Y | AC29: INT:~CORE~AERO_NA~SSO~RCE~AGRO_ZAF~MDSUK~RENEWABLE~RENEWCLUB_FRA~AERO_EMEA~AERO_BRA~HC_GCC~HC_APAC~HIGHER_EDU~CMPIF_CHN~EDU_APAC~UPSTREAM_MYS~DRILL_GLOBAL~DRILL_NAT~CL_PS_SUPPORTSTAFF_INTL~CL_HRG~ | AD29: GRANTPRICE | AE29: Grant Price Per Share/Unit | AF29: Price of the share or unit at the time of grant. | AG29: Round all prices to two decimal places (e.g., 12.125 should be entered as 12.13). If you are reporting a performance cash plan, co-investment shares and/or deferred bonus matching shares enter 1.00. | AH29: 50 | AI29: NULL | AK29: If(IsNull(:GRANTPRICE),Null,Round(:GRANTPRICE,2))
A30: A24261921654 | B30: 2025 MMPS Template | C30: SUBMISSIONUNIT | D30: 6 | E30: Primary Medium | F30: Y | G30: NULL | H30: Y | I30: 5377 | J30: NULL | K30: NULL | L30: NULL | M30: PICK | N30: PRIMARY_MEDIUM | O30: DDE087 | P30: USE | Q30: L | R30: United States | S30: USA | T30: USA | U30: 5 | V30: 0 | W30: W | X30: NULL | Y30: NULL | Z30: M | AA30: Y | AB30: Y | AC30: ~XXX~ | AD30: PRIMARY_MEDIUM | AE30: Primary Medium | AF30: The primary medium or business of the unit. Multiple Media Platforms is a combination of more than one medium. | AG30: NULL | AH30: NULL | AI30: NULL | AJ30: NULL | AK30: NULL
A31: A24261921654 | B31: 2025 MMPS Template | C31: SUBMISSIONINCUMBENT | D31: 6 | E31: Area/City Code | F31: Y | G31: ~DEFAULT:BR100~CHINA:CN001~EDUCATION:MY001~ | H31: Y | I31: 7966 | J31: NULL | K31: NULL | L31: NULL | M31: PICK | N31: AREACODE | O31: DDE236 | P31: USE | Q31: L | R31: United States | S31: USA | T31: USA | U31: 5 | V31: 0 | W31: W | X31: Refer to the Country Codes tab. For remote employees, report their nominal office or location to which they are assigned For all regions except Moscow, Moscow region, Saint-Petersburg and Leningrad region apply the same area/city code to incumbents based in regional capital city and outside regional capital city within a region (e.g., RU033 for Novosibirsk and Novosibirsk region/oblast). For the cities of and regions around Moscow and Saint-Petersburg, more granular codes are available and should be applied as follows: - Apply RU001 to incumbents based in Moscow - Apply RU002 to incumbents based in Moscow region/oblast - Apply RU003 to incumbents based in Saint-Petersburg - Apply RU004 to incumbents based in Leningrad region/oblast | Y31: NULL | Z31: M | AA31: Y | AB31: Y | AC31: ADV:~CORE_EMEA~CORE_LATAM~PSAR~;SCOPE:~CORE_APAC~CYCAR~ | AD31: AREACODE | AE31: Area/City Code | AF31: The area/city code of the primary office to which the incumbent is assigned. | AG31: Refer to the Country Codes tab. For remote employees, report their nominal office or location to which they are assigned For all regions except Moscow, Moscow region, Saint-Petersburg and Leningrad region apply the same area/city code to incumbents based in regional capital city and outside regional capital city within a region (e.g., RU033 for Novosibirsk and Novosibirsk region/oblast). For the cities of and regions around Moscow and Saint-Petersburg, more granular codes are available and should be applied as follows: - Apply RU001 to incumbents based in Moscow - Apply RU002 to incumbents based in Moscow region/oblast - Apply RU003 to incumbents based in Saint-Petersburg - Apply RU004 to incumbents based in Leningrad region/oblast | AH31: ~DEFAULT:BR100~CHINA:CN001~EDUCATION:MY001~ | AI31: NULL | AK31: upper(trim(:AREACODE))
A32: A24261921654 | B32: 2025 MMPS Template | C32: SUBMISSIONGRANT | D32: 7 | E32: Accounting Value per Share/Unit of Award | F32: N | G32: 52.25 | H32: Y | I32: 100 | J32: NULL | K32: NULL | L32: NULL | M32: MON | N32: ACCOUNTING | O32: ACCOUNTING | P32: USE | Q32: L | R32: United States | S32: USA | T32: USA | U32: 12 | V32: 2 | W32: W | X32: If you are reporting a performance cash award, enter 1.00. Values should reflect the grant date accounting value per unit of the award (e.g., 52.25 for a single performance share). All values should be rounded to two decimal places (e.g., 52.2512 should be entered as 52.25). The currency should be the same as the Grant Price Currency. | Y32: NULL | Z32: M | AA32: Y | AB32: Y | AC32: INT:~CORE~;HID:~MFG_LATAM~ | AD32: ACCOUNTING | AE32: Accounting Value per Share/Unit of Award | AF32: For each share-based award, please enter the Fair Value of the award at the date of grant. The Fair Value is the per share value of the award at grant as calculated under International Financial Reporting Standards - IFRS(2) or the equivalent under local country GAAP. Please note that this grant-date Fair Value may be provided by your finance department. | AG32: If you are reporting a performance cash award, enter 1.00. Values should reflect the grant date accounting value per unit of the award (e.g., 52.25 for a single performance share). All values should be rounded to two decimal places (e.g., 52.2512 should be entered as 52.25). The currency should be the same as the Grant Price Currency. | AH32: 52.25 | AI32: NULL | AK32: If(IsNull(:ACCOUNTING),Null,Round(:ACCOUNTING,2))
A33: A24261921654 | B33: 2025 MMPS Template | C33: SUBMISSIONUNIT | D33: 7 | E33: Newspaper Circulation | F33: Y | G33: NULL | H33: Y | I33: 22814 | J33: NULL | K33: NULL | L33: NULL | M33: NUM | N33: NEWSPAPER_CIRCULATION | O33: DDE098 | P33: USE | Q33: L | R33: United States | S33: USA | T33: USA | U33: 12 | V33: 0 | W33: W | X33: NULL | Y33: NULL | Z33: M | AA33: Y | AB33: Y | AC33: ~XXX~ | AD33: NEWSPAPER_CIRCULATION | AE33: Newspaper Circulation | AF33: The audited newspaper circulation (in whole numbers) for the most recent fiscal year, not including potential online audiences. | AG33: NULL | AH33: NULL | AI33: NULL | AJ33: NULL | AK33: NULL
A34: A24261921654 | B34: 2025 MMPS Template | C34: SUBMISSIONINCUMBENT | D34: 7 | E34: Reports to Job Code | F34: N | G34: NULL | H34: Y | I34: 405 | J34: NULL | K34: NULL | L34: NULL | M34: CHAR | N34: RPT2JOB | O34: DDE180 | P34: USE | Q34: L | R34: United States | S34: USA | T34: USA | U34: 255 | V34: 0 | W34: W | X34: NULL | Y34: NULL | Z34: M | AA34: Y | AB34: Y | AC34: ~XXX~ | AD34: RPT2JOB | AE34: Reports to Job Code | AF34: NULL | AG34: NULL | AH34: NULL | AI34: NULL | AJ34: NULL | AK34: NULL
A35: A24261921654 | B35: 2025 MMPS Template | C35: SUBMISSIONCONTACT | D35: 7 | E35: Report Recipient Postal/ZIP Code | F35: N | G35: 10017 | H35: Y | I35: 996 | J35: NULL | K35: NULL | L35: NULL | M35: CHAR | N35: CONTACT_ZIPCODE | O35: DDE040 | P35: USE | Q35: L | R35: United States | S35: USA | T35: USA | U35: 250 | V35: 0 | W35: W | Y35: NULL | Z35: M | AA35: Y | AB35: Y | AC35: ~CORE_NA~AERO_NA~ | AD35: CONTACT_ZIPCODE | AE35: Report Recipient Postal/ZIP Code | AF35: Report Recipient Postal/ZIP Code | AH35: 10017 | AI35: NULL | AK35: NULL
A36: A24261921654 | B36: 2025 MMPS Template | C36: SUBMISSIONCOMPANY | D36: 7 | E36: Book Publishing | F36: Y | G36: Y [Yes] | H36: Y | I36: 1118 | J36: NULL | K36: NULL | L36: NULL | M36: BOOL | N36: BOOK_PUBLISHING | O36: DDE057 | P36: USE | Q36: L | R36: United States | S36: USA | T36: USA | U36: 1 | V36: 0 | W36: W | X36: N-No Y-Yes | Y36: NULL | Z36: M | AA36: Y | AB36: Y | AC36: ADV:~TMG~ | AD36: BOOK_PUBLISHING | AE36: Book Publishing | AF36: The media industries in which the organization is involved. | AG36: N-No Y-Yes | AH36: Y [Yes] | AI36: NULL | AK36: NULL
A37: A24261921654 | B37: 2025 MMPS Template | C37: SUBMISSIONCONTACT | D37: 8 | E37: Report Recipient Country | F37: N | G37: USA | H37: Y | I37: 998 | J37: NULL | K37: NULL | L37: NULL | M37: CHAR | N37: CONTACT_COUNTRY | O37: DDE042 | P37: USE | Q37: L | R37: United States | S37: USA | T37: USA | U37: 250 | V37: 0 | W37: W | Y37: NULL | Z37: M | AA37: Y | AB37: Y | AC37: ~CORE_NA~AERO_NA~ | AD37: CONTACT_COUNTRY | AE37: Report Recipient Country | AF37: Report Recipient Country | AH37: USA | AI37: NULL | AK37: NULL
A38: A24261921654 | B38: 2025 MMPS Template | C38: SUBMISSIONGRANT | D38: 8 | E38: Accounting Value per Share/Unit of Award Curr | F38: N | G38: NULL | H38: N | I38: 101 | J38: 100 | K38: 100 | L38: C | M38: CHAR | N38: ACCOUNTINGCURR | O38: ACCOUNTINGCURR | P38: USE | Q38: L | R38: United States | S38: USA | T38: USA | U38: 12 | V38: 0 | W38: W | X38: NULL | Y38: NULL | Z38: M | AA38: Y | AB38: Y | AC38: ~CORE~;HID:~MFG_LATAM~ | AD38: ACCOUNTINGCURR | AE38: Accounting Value per Share/Unit of Award Curr | AF38: Accounting Value per Share/Unit of Award Currency | AG38: NULL | AH38: NULL | AI38: NULL | AK38: :GRANTPRICECURR
A39: A24261921654 | B39: 2025 MMPS Template | C39: SUBMISSIONCOMPANY | D39: 8 | E39: Business to Business Media | F39: Y | G39: Y [Yes] | H39: Y | I39: 1119 | J39: NULL | K39: NULL | L39: NULL | M39: BOOL | N39: B_TO_B_MEDIA | O39: DDE058 | P39: USE | Q39: L | R39: United States | S39: USA | T39: USA | U39: 1 | V39: 0 | W39: W | X39: N-No Y-Yes | Y39: NULL | Z39: M | AA39: Y | AB39: Y | AC39: ADV:~TMG~ | AD39: B_TO_B_MEDIA | AE39: Business to Business Media | AF39: The media industries in which the organization is involved. | AG39: N-No Y-Yes | AH39: Y [Yes] | AI39: NULL | AK39: NULL
A40: A24261921654 | B40: 2025 MMPS Template | C40: SUBMISSIONUNIT | D40: 8 | E40: Newspaper Format | F40: Y | G40: NULL | H40: Y | I40: 37276 | J40: NULL | K40: NULL | L40: NULL | M40: PICK | N40: NEWSPAPER_FORMAT | O40: DDE101 | P40: USE | Q40: L | R40: United States | S40: USA | T40: USA | U40: 5 | V40: 0 | W40: W | X40: 1 Daily 2 Non-Daily/Weekly/Other | Y40: NULL | Z40: M | AA40: Y | AB40: Y | AC40: ~XXX~ | AD40: NEWSPAPER_FORMAT | AE40: Newspaper Format | AF40: How often the newspaper is published. | AG40: 1 Daily 2 Non-Daily/Weekly/Other | AH40: NULL | AI40: NULL | AJ40: NULL | AK40: NULL
...

Sheet CPMIF
A1: versionid | B1: versionname | C1: tablename | D1: sequence | E1: elementname | F1: turnaroundind | G1: sampledata | H1: exportind | I1: elementid | J1: parentelementid | K1: parentelementid | L1: relationshiptype | M1: elementtype | N1: fieldname | O1: columnname | P1: languagecode | Q1: ddetype | R1: countrydesc | S1: countrycode | T1: regioncode | U1: elementlength | V1: elementprecision | W1: collectionunits | X1: guidelines | Y1: csfieldname | Z1: colusage | AA1: ascentnullableind | AB1: nullableind | AC1: note | AD1: elementname | AE1: elementdesc | AF1: guidelines | AG1: sampledata | AH1: excelformula | AI1: expression | AJ1: loadrule
A2: A24149240511 | B2: 2025 Capital Market Project Investment and Financing Compensation Survey - China | C2: SUBMISSIONUNIT | D2: 1 | E2: Unit Number | F2: Y | G2: 1 | H2: N | I2: 10 | J2: NULL | K2: NULL | L2: NULL | M2: CHAR | N2: UNITNUM | O2: UNITNUM | P2: USE | Q2: L | R2: China | S2: CHN | T2: APC | U2: 12 | V2: 0 | W2: W | X2: Enter a unique three-digit code (e.g., 001, 002) to identify each unit. Unit numbers will be assigned to the corresponding incumbent in these units in the Incumbent Data worksheet. | Y2: NULL | Z2: M | AA2: N | AB2: N | AC2: HID:~CORE~AERO_NA~SSO~RCE~AGRO_ZAF~MDSUK~YOUNGGRAD~MFG_LATAM~RENEWABLE~RENEWCLUB_FRA~AERO_EMEA~AERO_BRA~HC_GCC~HC_APAC~HIGHER_EDU~CMPIF_CHN~EDU_APAC~UPSTREAM_MYS~LEGAL_FEE_EARNERS~CL_PS_SUPPORTSTAFF_INTL~CL_HRG~ | AD2: Unit Number | AE2: The unit number for the incumbent's unit. | AF2: Enter a unique three-digit code (e.g., 001, 002) to identify each unit. Unit numbers will be assigned to the corresponding incumbent in these units in the Incumbent Data worksheet. | AG2: 1 | AH2: NULL | AJ2: NULL
A3: A24149240511 | B3: 2025 Capital Market Project Investment and Financing Compensation Survey - China | C3: SUBMISSIONINCUMBENT | D3: 1 | E3: Country Code | F3: Y | G3: JPN | H3: Y | I3: 14 | J3: NULL | K3: NULL | L3: NULL | M3: CHAR | N3: COUNTRYCODE | O3: COUNTRYCODE | P3: USE | Q3: L | R3: China | S3: CHN | T3: APC | U3: 5 | V3: 0 | W3: W | X3: Refer to the Country Codes tab. | Y3: NULL | Z3: M | AA3: N | AB3: N | AC3: INT:~CORE~AERO_NA~SSO~RCE~AGRO_ZAF~MDSUK~YOUNGGRAD~MFG_LATAM~RENEWABLE~RENEWCLUB_FRA~AERO_EMEA~AERO_BRA~HC_GCC~HC_APAC~HIGHER_EDU~CMPIF_CHN~EDU_APAC~UPSTREAM_MYS~DRILL_GLOBAL~DRILL_NAT~LEGAL_FEE_EARNERS~CL_PS_SUPPORTSTAFF_INTL~CL_HRG~PSAR~INT~ | AD3: Country Code | AE3: The country code of the primary office to which they are assigned. | AF3: Refer to the Country Codes tab. | AG3: JPN | AH3: NULL | AJ3: If(:COUNTRYCODE="xx",null,Trim(Upper(:COUNTRYCODE)))
A4: A24149240511 | B4: 2025 Capital Market Project Investment and Financing Compensation Survey - China | C4: SUBMISSIONGRANT | D4: 1 | E4: Case Number | F4: N | G4: NULL | H4: N | I4: 22 | J4: NULL | K4: NULL | L4: NULL | M4: CHAR | N4: CASEID | O4: CASEID | P4: USE | Q4: L | R4: China | S4: CHN | T4: APC | U4: 7 | V4: 0 | W4: W | Y4: NULL | Z4: M | AA4: N | AB4: N | AC4: ~CORE~AERO_NA~;HID:RCE~AGRO_ZAF~MDSUK~YOUNGGRAD~SSO~MFG_LATAM~RENEWABLE~RENEWCLUB_FRA~AERO_EMEA~AERO_BRA~HC_GCC~HC_APAC~HIGHER_EDU~CMPIF_CHN~EDU_APAC~UPSTREAM_MYS~DRILL_GLOBAL~DRIL_NAT~LEGAL_FEE_EARNERS~CL_PS_SUPPORTSTAFF_INTL~ | AD4: Case Number | AE4: Seven-digit case number to uniquely identify each incumbent. | AG4: NULL | AH4: NULL | AJ4: If(:CASEID="XXXX",null,LPad(:CASEID,6,"0"))
A5: A24149240511 | B5: 2025 Capital Market Project Investment and Financing Compensation Survey - China | C5: SUBMISSIONCOMPANY | D5: 1 | E5: Participating Entity Name | F5: N | G5: Your Company Name | H5: Y | I5: 566 | J5: NULL | K5: NULL | L5: NULL | M5: CHAR | N5: COMPANY_NAME | O5: DDE038 | P5: USE | Q5: L | R5: China | S5: CHN | T5: APC | U5: 255 | V5: 0 | W5: W | X5: NULL | Y5: NULL | Z5: M | AA5: Y | AB5: Y | AC5: ~CORE~AERO_NA~SSO~RCE~AGRO_ZAF~MDSUK~YOUNGGRAD~MFG_LATAM~RENEWABLE~RENEWCLUB_FRA~AERO_EMEA~AERO_BRA~HC_GCC~HC_APAC~HIGHER_EDU~CMPIF_CHN~EDU_APAC~UPSTREAM_MYS~DRILL_GLOBAL~DRILL_NAT~LEGAL_FEE_EARNERS~CL_PS_SUPPORTSTAFF_INTL~CL_HRG~PSAR~INT~ | AD5: Participating Entity Name | AE5: The name of your organization. | AF5: NULL | AG5: Your Company Name | AH5: NULL | AJ5: NULL
A6: A24149240511 | B6: 2025 Capital Market Project Investment and Financing Compensation Survey - China | C6: SUBMISSIONCONTACT | D6: 1 | E6: Cash Compensation Contact Name | F6: N | G6: Mr. Mike Smith | H6: Y | I6: 982 | J6: NULL | K6: NULL | L6: NULL | M6: CHAR | N6: CASH_CONTACT_NAME | O6: DDE026 | P6: USE | Q6: L | R6: China | S6: CHN | T6: APC | U6: 250 | V6: 0 | W6: W | Y6: NULL | Z6: M | AA6: Y | AB6: Y | AC6: ~CORE~AERO_NA~SSO~RCE~AGRO_ZAF~MDSUK~YOUNGGRAD~MFG_LATAM~RENEWABLE~RENEWCLUB_FRA~AERO_EMEA~AERO_BRA~HC_GCC~HC_APAC~HIGHER_EDU~CMPIF_CHN~EDU_APAC~UPSTREAM_MYS~DRILL_GLOBAL~DRILL_NAT~LEGAL_FEE_EARNERS~CL_PS_SUPPORTSTAFF_INTL~CL_HRG~PSAR~INT~ | AD6: Cash Compensation Contact Name | AE6: Cash Compensation Contact Name | AG6: Mr. Mike Smith | AH6: NULL | AJ6: NULL
A7: A24149240511 | B7: 2025 Capital Market Project Investment and Financing Compensation Survey - China | C7: SUBMISSIONGRANT | D7: 2 | E7: Long-Term Incentive Plan Type | F7: N | G7: PP | H7: Y | I7: 83 | J7: NULL | K7: NULL | L7: NULL | M7: PICK | N7: PLANTYPE | O7: PLANTYPE | P7: USE | Q7: L | R7: China | S7: CHN | T7: APC | U7: 5 | V7: 0 | W7: W | X7: PP-Performance Plan Awards: Performance Plan Awards are contingent grants of cash or stock that are earned in whole or in part according to the degree of achievement of performance goals over a defined period (usually three years). RS-Restricted Stock/Stock Units: Restricted Stock/Stock Units are grants of stock or stock units at no or nominal cost. The restrictions and risk of forfeiture lapse with continued employment over a period of years. If vesting also includes a performance condition, such condition is considered to be nominal with a high likelihood of being attained. Dividends or dividend equivalents may be paid or accrued during the restricted period. SO-Stock Options/SARs: Stock Options are rights to purchase a fixed number of shares of a company's stock, at a stated price for a specified period of time. Stock Appreciation Rights (SARs) are rights to receive payment equal in value to the appreciation on a share of stock between the date on which the SAR was granted and the date on which the employee exercises his/her appreciation rights. | Y7: NULL | Z7: M | AA7: Y | AB7: Y | AC7: INT:~CORE~AERO_NA~SSO~RCE~AGRO_ZAF~MDSUK~MFG_LATAM~RENEWABLE~RENEWCLUB_FRA~AERO_EMEA~AERO_BRA~HC_GCC~HC_APAC~HIGHER_EDU~CMPIF_CHN~EDU_APAC~UPSTREAM_MYS~DRILL_GLOBAL~DRILL_NAT~CL_PS_SUPPORTSTAFF_INTL~CL_HRG~;HID:~PSAR~INT~ | AD7: Long-Term Incentive Plan Type | AE7: Type of long-term grant data being reported. | AF7: PP-Performance Plan Awards: Performance Plan Awards are contingent grants of cash or stock that are earned in whole or in part according to the degree of achievement of performance goals over a defined period (usually three years). RS-Restricted Stock/Stock Units: Restricted Stock/Stock Units are grants of stock or stock units at no or nominal cost. The restrictions and risk of forfeiture lapse with continued employment over a period of years. If vesting also includes a performance condition, such condition is considered to be nominal with a high likelihood of being attained. Dividends or dividend equivalents may be paid or accrued during the restricted period. SO-Stock Options/SARs: Stock Options are rights to purchase a fixed number of shares of a company's stock, at a stated price for a specified period of time. Stock Appreciation Rights (SARs) are rights to receive payment equal in value to the appreciation on a share of stock between the date on which the SAR was granted and the date on which the employee exercises his/her appreciation rights. | AG7: PP | AH7: NULL | AJ7: UPPER(TRIM(:PLANTYPE))
A8: A24149240511 | B8: 2025 Capital Market Project Investment and Financing Compensation Survey - China | C8: SUBMISSIONCOMPANY | D8: 2 | E8: Participating Entity Country | F8: Y | G8: JPN [Japan] | H8: Y | I8: 35000 | J8: NULL | K8: NULL | L8: NULL | M8: PICK | N8: ISO3 | O8: DDE207 | P8: USE | Q8: L | R8: China | S8: CHN | T8: APC | U8: 5 | V8: 0 | W8: W | X8: Refer to the Country Codes tab. | Y8: NULL | Z8: M | AA8: N | AB8: Y | AC8: DSW:~CORE~AERO_NA~SSO~RCE~AGRO_ZAF~MDSUK~YOUNGGRAD~MFG_LATAM~RENEWABLE~RENEWCLUB_FRA~AERO_EMEA~AERO_BRA~HC_GCC~HC_APAC~HIGHER_EDU~CMPIF_CHN~EDU_APAC~UPSTREAM_MYS~DRILL_GLOBAL~DRILL_NAT~LEGAL_FEE_EARNERS~CL_PS_SUPPORTSTAFF_INTL~CL_HRG~PSAR~ | AD8: Participating Entity Country | AE8: The country where the participating entity is based/headquartered. | AF8: Refer to the Country Codes tab. | AG8: JPN [Japan] | AH8: NULL | AJ8: NULL
A9: A24149240511 | B9: 2025 Capital Market Project Investment and Financing Compensation Survey - China | C9: SUBMISSIONUNIT | D9: 2 | E9: Comments | F9: N | G9: NULL | H9: N | I9: 80 | J9: NULL | K9: NULL | L9: NULL | M9: CHAR | N9: COMMENTS | O9: COMMENTS | P9: USE | Q9: L | R9: China | S9: CHN | T9: APC | U9: 255 | V9: 0 | W9: W | X9: NULL | Y9: NULL | Z9: M | AA9: Y | AB9: Y | AC9: ~CORE~AERO_NA~SSO~RCE~AGRO_ZAF~MDSUK~YOUNGGRAD~MFG_LATAM~RENEWABLE~RENEWCLUB_FRA~AERO_EMEA~AERO_BRA~HC_GCC~HC_APAC~HIGHER_EDU~CMPIF_CHN~EDU_APAC~UPSTREAM_MYS~DRILL_GLOBAL~DRILL_NAT~LEGAL_FEE_EARNERS~CL_PS_SUPPORTSTAFF_INTL~PSAR~INT~ | AD9: Comments | AE9: Unit Comments | AF9: NULL | AG9: NULL | AH9: NULL | AJ9: NULL
A10: A24149240511 | B10: 2025 Capital Market Project Investment and Financing Compensation Survey - China | C10: SUBMISSIONCONTACT | D10: 2 | E10: Cash Compensation Contact Title | F10: N | G10: Cash Contact | H10: Y | I10: 983 | J10: NULL | K10: NULL | L10: NULL | M10: CHAR | N10: CASH_CONTACT_TITLE | O10: DDE027 | P10: USE | Q10: L | R10: China | S10: CHN | T10: APC | U10: 250 | V10: 0 | W10: W | Y10: NULL | Z10: M | AA10: Y | AB10: Y | AC10: ~CORE~AERO_NA~SSO~RCE~AGRO_ZAF~MDSUK~YOUNGGRAD~MFG_LATAM~RENEWABLE~RENEWCLUB_FRA~AERO_EMEA~AERO_BRA~HC_GCC~HC_APAC~HIGHER_EDU~CMPIF_CHN~EDU_APAC~UPSTREAM_MYS~DRILL_GLOBAL~DRILL_NAT~LEGAL_FEE_EARNERS~CL_PS_SUPPORTSTAFF_INTL~CL_HRG~PSAR~INT~ | AD10: Cash Compensation Contact Title | AE10: Cash Compensation Contact Title | AG10: Cash Contact | AH10: NULL | AJ10: NULL
A11: A24149240511 | B11: 2025 Capital Market Project Investment and Financing Compensation Survey - China | C11: SUBMISSIONINCUMBENT | D11: 2 | E11: Case Number | F11: Y | G11: 1 | H11: N | I11: 12 | J11: NULL | K11: NULL | L11: NULL | M11: CHAR | N11: CASEID | O11: CASEID | P11: USE | Q11: L | R11: China | S11: CHN | T11: APC | U11: 7 | V11: 0 | W11: W | X11: Number the cases starting with 0000001. | Y11: NULL | Z11: M | AA11: N | AB11: N | AC11: ADV,DSW:~CORE~AERO_NA~RENEWABLE~RENEWCLUB_FRA~RCE~MDSUK~AERO_EMEA~AERO_BRA~CL_HRG~PSAR~;HID:~AGRO_ZAF~YOUNGGRAD~SSO~MFG_LATAM~HC_GCC~HC_APAC~HIGHER_EDU~CMPIF_CHN~EDU_APAC~UPSTREAM_MYS~DRILL_GLOBAL~DRILL_NAT~LEGAL_FEE_EARNERS~CL_PS_SUPPORTSTAFF_INTL~ | AD11: Case Number | AE11: Seven-digit case number to uniquely identify each incumbent. | AF11: Number the cases starting with 0000001. | AG11: 1 | AH11: NULL | AJ11: If(:CASEID="XXXX",null,LPad(:CASEID,6,"0"))
A12: A24149240511 | B12: 2025 Capital Market Project Investment and Financing Compensation Survey - China | C12: SUBMISSIONGRANT | D12: 3 | E12: Long-Term Incentive Plan Number | F12: N | G12: PP01 | H12: N | I12: 23 | J12: NULL | K12: NULL | L12: NULL | M12: CHAR | N12: PLANCODE | O12: PLANCODE | P12: USE | Q12: L | R12: China | S12: CHN | T12: APC | U12: 12 | V12: 0 | W12: W | X12: If under the same plan different incumbents have different vesting arrangements, report each plan separately. For example, if a performance cash plan has a TSR performance condition applicable to board member and an EPS performance condition applicable to all other incumbents, code each as a separate plan. | Y12: NULL | Z12: M | AA12: Y | AB12: Y | AC12: INT:~CORE~AERO_NA~RENEWABLE~AERO_EMEA~AERO_BRA~MDSUK~CL_HRG~;HID:~RCE~AGRO_ZAF~YOUNGGRAD~SSO~MFG_LATAM~HC_GCC~HC_APAC~HIGHER_EDU~CMPIF_CHN~EDU_APAC~UPSTREAM_MYS~RENEWCLUB_FRA~DRILL_GLOBAL~DRILL_NAT~CL_PS_SUPPORTSTAFF_INTL~ | AD12: Long-Term Incentive Plan Number | AE12: The plan number is located on each plan type worksheet on the data submission spreadsheet and is required for each grant. The Long-Term Plan Number (e.g., PP01) ties the shares granted with the plan data. | AF12: If under the same plan different incumbents have different vesting arrangements, report each plan separately. For example, if a performance cash plan has a TSR performance condition applicable to board member and an EPS performance condition applicable to all other incumbents, code each as a separate plan. | AG12: PP01 | AH12: NULL | AJ12: TRIM(UPPER(:PLANCODE))
A13: A24149240511 | B13: 2025 Capital Market Project Investment and Financing Compensation Survey - China | C13: SUBMISSIONCONTACT | D13: 3 | E13: Cash Compensation Contact Phone | F13: N | G13: +1 (212) 555-1111 | H13: Y | I13: 984 | J13: NULL | K13: NULL | L13: NULL | M13: CHAR | N13: CASH_CONTACT_PHONE | O13: DDE028 | P13: USE | Q13: L | R13: China | S13: CHN | T13: APC | U13: 250 | V13: 0 | W13: W | Y13: NULL | Z13: M | AA13: Y | AB13: Y | AC13: ~CORE~AERO_NA~SSO~RCE~AGRO_ZAF~MDSUK~YOUNGGRAD~MFG_LATAM~RENEWABLE~RENEWCLUB_FRA~AERO_EMEA~AERO_BRA~HC_GCC~HC_APAC~HIGHER_EDU~CMPIF_CHN~EDU_APAC~UPSTREAM_MYS~DRILL_GLOBAL~DRILL_NAT~LEGAL_FEE_EARNERS~CL_PS_SUPPORTSTAFF_INTL~CL_HRG~PSAR~INT~ | AD13: Cash Compensation Contact Phone | AE13: Cash Compensation Contact Phone | AG13: +1 (212) 555-1111 | AH13: NULL | AJ13: NULL
A14: A24149240511 | B14: 2025 Capital Market Project Investment and Financing Compensation Survey - China | C14: SUBMISSIONCOMPANY | D14: 3 | E14: Participating Entity Currency of Organization Elements | F14: N | G14: JPY [Japan Yen] | H14: Y | I14: 34982 | J14: NULL | K14: NULL | L14: NULL | M14: PICK | N14: ENTITY_CURR | O14: DDE191 | P14: USE | Q14: L | R14: China | S14: CHN | T14: APC | U14: 5 | V14: 0 | W14: W | X14: Refer to the Country Codes tab. | Y14: NULL | Z14: M | AA14: Y | AB14: Y | AC14: INT:~CORE~AERO_NA~SSO~RCE~AGRO_ZAF~MDSUK~YOUNGGRAD~MFG_LATAM~RENEWABLE~RENEWCLUB_FRA~AERO_EMEA~AERO_BRA~HC_GCC~HC_APAC~HIGHER_EDU~CMPIF_CHN~EDU_APAC~UPSTREAM_MYS~DRILL_GLOBAL~DRILL_NAT~LEGAL_FEE_EARNERS~CL_PS_SUPPORTSTAFF_INTL~CL_HRG~PSAR~INT~ | AD14: Participating Entity Currency of Organization Elements | AE14: The currency code for all Participating Entity elements (e.g., Annual Revenue). | AF14: Refer to the Country Codes tab. | AG14: JPY [Japan Yen] | AH14: NULL | AJ14: NULL
A15: A24149240511 | B15: 2025 Capital Market Project Investment and Financing Compensation Survey - China | C15: SUBMISSIONINCUMBENT | D15: 3 | E15: Area/City Code | F15: Y | G15: JP001 | H15: Y | I15: 7966 | J15: NULL | K15: NULL | L15: NULL | M15: PICK | N15: AREACODE | O15: DDE236 | P15: USE | Q15: L | R15: China | S15: CHN | T15: APC | U15: 5 | V15: 0 | W15: W | X15: Refer to the Country Codes tab. For remote employees, report their nominal office or location to which they are assigned For all regions except Moscow, Moscow region, Saint-Petersburg and Leningrad region apply the same area/city code to incumbents based in regional capital city and outside regional capital city within a region (e.g., RU033 for Novosibirsk and Novosibirsk region/oblast). For the cities of and regions around Moscow and Saint-Petersburg, more granular codes are available and should be applied as follows: - Apply RU001 to incumbents based in Moscow - Apply RU002 to incumbents based in Moscow region/oblast - Apply RU003 to incumbents based in Saint-Petersburg - Apply RU004 to incumbents based in Leningrad region/oblast | Y15: NULL | Z15: M | AA15: Y | AB15: Y | AC15: ADV:~CORE_EMEA~CORE_LATAM~SSO~RCE~AGRO_ZAF~MDSUK~YOUNGGRAD~MFG_LATAM~RENEWABLE~RENEWCLUB_FRA~AERO_EMEA~AERO_BRA~HC_GCC~HIGHER_EDU~DRILL_GLOBAL~DRILL_NAT_INTL~LEGAL_FEE_EARNERS~CL_PS_SUPPORTSTAFF_INTL~CL_HRG~;PUB:~PSAR~;SCOPE:~CORE_APAC~CMPIF_CHN~EDU_APAC~UPSTREAM_MYS~SSO_APAC~RCE_APAC~RENEWABLE_APAC~HC_APAC~ | AD15: Area/City Code | AE15: The area/city code of the primary office to which the incumbent is assigned. | AF15: Refer to the Country Codes tab. For remote employees, report their nominal office or location to which they are assigned For all regions except Moscow, Moscow region, Saint-Petersburg and Leningrad region apply the same area/city code to incumbents based in regional capital city and outside regional capital city within a region (e.g., RU033 for Novosibirsk and Novosibirsk region/oblast). For the cities of and regions around Moscow and Saint-Petersburg, more granular codes are available and should be applied as follows: - Apply RU001 to incumbents based in Moscow - Apply RU002 to incumbents based in Moscow region/oblast - Apply RU003 to incumbents based in Saint-Petersburg - Apply RU004 to incumbents based in Leningrad region/oblast | AG15: JP001 | AH15: NULL | AJ15: upper(trim(:AREACODE))
A16: A24149240511 | B16: 2025 Capital Market Project Investment and Financing Compensation Survey - China | C16: SUBMISSIONCONTACT | D16: 4 | E16: Cash Compensation Contact E-mail | F16: N | G16: mike.smith@example.com | H16: Y | I16: 985 | J16: NULL | K16: NULL | L16: NULL | M16: CHAR | N16: CASH_CONTACT_EMAIL | O16: DDE029 | P16: USE | Q16: L | R16: China | S16: CHN | T16: APC | U16: 250 | V16: 0 | W16: W | Y16: NULL | Z16: M | AA16: Y | AB16: Y | AC16: ~CORE~AERO_NA~SSO~RCE~AGRO_ZAF~MDSUK~YOUNGGRAD~MFG_LATAM~RENEWABLE~RENEWCLUB_FRA~AERO_EMEA~AERO_BRA~HC_GCC~HC_APAC~HIGHER_EDU~CMPIF_CHN~EDU_APAC~UPSTREAM_MYS~DRILL_GLOBAL~DRILL_NAT~LEGAL_FEE_EARNERS~CL_PS_SUPPORTSTAFF_INTL~CL_HRG~PSAR~INT~ | AD16: Cash Compensation Contact E-mail | AE16: Cash Compensation Contact E-mail | AG16: mike.smith@example.com | AH16: NULL | AJ16: NULL
A17: A24149240511 | B17: 2025 Capital Market Project Investment and Financing Compensation Survey - China | C17: SUBMISSIONCOMPANY | D17: 4 | E17: Participating Entity Annual Revenue | F17: N | G17: 76000000 | H17: Y | I17: 172 | J17: NULL | K17: NULL | L17: NULL | M17: MON | N17: ENTITY_REV | O17: DDE005 | P17: USE | Q17: L | R17: China | S17: CHN | T17: APC | U17: 15 | V17: 0 | W17: W | X17: For the headquarter country, enter global revenue. For banks this is usually net interest income plus (where relevant/quantifiable) other revenue such as investment and fee income. For insurance companies, this is usually gross premium income (a.k.a. "gross written premiums") plus (where relevant/quantifiable) other revenue such as investment and fee income. Do not deduct premiums ceded to reinsurers for de-risking purposes. Note: enter all financial data in whole numbers. | Y17: NULL | Z17: M | AA17: Y | AB17: Y | AC17: INT:~CORE_APAC~CORE_EMEA~CORE_LATAM~SSO~RCE~AGRO_ZAF~RENEWABLE~RENEWCLUB_FRA~AERO_EMEA~AERO_BRA~HC_GCC~HC_APAC~HIGHER_EDU~CMPIF_CHN~EDU_APAC~UPSTREAM_MYS~DRILL_GLOBAL~DRILL_NAT_INTL~DRILL_NAT_NA~CL_PS_SUPPORTSTAFF_INTL~CL_HRG~;ADV:~CORE_NA~AERO_NA~MDSUK~YOUNGGRAD~MFG_LATAM~LEGAL_FEE_EARNERS~PSAR~INT~ | AD17: Participating Entity Annual Revenue | AE17: The participating entity's total annual gross revenue for the most recent fiscal year. | AF17: For the headquarter country, enter global revenue. For banks this is usually net interest income plus (where relevant/quantifiable) other revenue such as investment and fee income. For insurance companies, this is usually gross premium income (a.k.a. "gross written premiums") plus (where relevant/quantifiable) other revenue such as investment and fee income. Do not deduct premiums ceded to reinsurers for de-risking purposes. Note: enter all financial data in whole numbers. | AG17: 76000000 | AH17: NULL | AJ17: NULL
A18: A24149240511 | B18: 2025 Capital Market Project Investment and Financing Compensation Survey - China | C18: SUBMISSIONGRANT | D18: 4 | E18: Grant Date | F18: N | G18: 44929 | H18: Y | I18: 196 | J18: NULL | K18: NULL | L18: NULL | M18: DATE | N18: GRANT_DATE | O18: DDE001 | P18: USE | Q18: L | R18: China | S18: CHN | T18: APC | U18: 8 | V18: 0 | W18: W | X18: Provide date of grants in the last 12 months. Enter the date in your normal date format (DD/MM/YY or MM/DD/YY depending on user default). For special grants provided in lieu of annual grants and for multi-year or mega grants, please enter your most recent grant which could be more than 12 months ago. | Y18: NULL | Z18: M | AA18: Y | AB18: Y | AC18: DSW,INT:~CORE~AERO_NA~SSO~RCE~AGRO_ZAF~MDSUK~MFG_LATAM~RENEWABLE~RENEWCLUB_FRA~AERO_EMEA~AERO_BRA~HC_GCC~HC_APAC~HIGHER_EDU~CMPIF_CHN~EDU_APAC~UPSTREAM_MYS~DRILL_GLOBAL~DRILL_NAT~CL_PS_SUPPORTSTAFF_INTL~CL_HRG~INT~ | AD18: Grant Date | AE18: Date the grant was made. | AF18: Provide date of grants in the last 12 months. Enter the date in your normal date format (DD/MM/YY or MM/DD/YY depending on user default). For special grants provided in lieu of annual grants and for multi-year or mega grants, please enter your most recent grant which could be more than 12 months ago. | AG18: 44929 | AH18: NULL | AJ18: NULL
A19: A24149240511 | B19: 2025 Capital Market Project Investment and Financing Compensation Survey - China | C19: SUBMISSIONINCUMBENT | D19: 4 | E19: Postal/ZIP Code | F19: Y | G19: 75008 | H19: Y | I19: 246 | J19: NULL | K19: NULL | L19: NULL | M19: CHAR | N19: POSTZIPCODE | O19: DDE145 | P19: USE | Q19: L | R19: China | S19: CHN | T19: APC | U19: 12 | V19: 0 | W19: W | X19: For home based employees or equivalent, please provide the postcode of their nominal or primary office. | Y19: NULL | Z19: M | AA19: Y | AB19: Y | AC19: ~CORE_APAC~CORE_EMEA~CORE_NA~AERO_NA~CORE_BMU~SSO_APAC~SSO_EMEA~RCE_APAC~RCE_EMEA~AGRO_ZAF~MDSUK~YOUNGGRAD~RENEWABLE_APAC~RENEWABLE_EMEA~RENEWCLUB_FRA~AERO_EMEA~HC_GCC~HC_APAC~HIGHER_EDU~CMPIF_CHN~EDU_APAC~UPSTREAM_MYS~DRILL_GLOBAL~DRILL_NAT_APAC~DRILL_NAT_EMEA~DRILL_NAT_NA~LEGAL_FEE_EARNERS~CL_PS_SUPPORTSTAFF_INTL~CL_HRG~PSAR~INT~ | AD19: Postal/ZIP Code | AE19: The Postal/ZIP code for the incumbent's primary work location. | AF19: For home based employees or equivalent, please provide the postcode of their nominal or primary office. | AG19: 75008 | AH19: NULL | AJ19: Trim(:POSTZIPCODE)
A20: A24149240511 | B20: 2025 Capital Market Project Investment and Financing Compensation Survey - China | C20: SUBMISSIONINCUMBENT | D20: 5 | E20: Unique Incumbent Identifier | F20: Y | G20: 12345 | H20: Y | I20: 241 | J20: NULL | K20: NULL | L20: NULL | M20: CHAR | N20: IDENT | O20: DDE140 | P20: USE | Q20: L | R20: China | S20: CHN | T20: APC | U20: 60 | V20: 0 | W20: W | X20: Do not use personal identifying data (e.g., employee names, initials, or government ID such as Social Security or Social Insurance number). Use consistent identifiers year over year. | Y20: NULL | Z20: M | AA20: Y | AB20: Y | AC20: ADV:~CORE~AERO_NA~SSO~RCE~AGRO_ZAF~MDSUK~YOUNGGRAD~MFG_LATAM~RENEWABLE~RENEWCLUB_FRA~AERO_EMEA~AERO_BRA~HC_GCC~HC_APAC~HIGHER_EDU~CMPIF_CHN~EDU_APAC~UPSTREAM_MYS~DRILL_GLOBAL~DRILL_NAT~LEGAL_FEE_EARNERS~CL_PS_SUPPORTSTAFF_INTL~CL_HRG~PSAR~ADV~ | AD20: Unique Incumbent Identifier | AE20: Internal reference number, which is specific and unique to each individual. | AF20: Do not use personal identifying data (e.g., employee names, initials, or government ID such as Social Security or Social Insurance number). Use consistent identifiers year over year. | AG20: 12345 | AH20: NULL | AJ20: NULL
A21: A24149240511 | B21: 2025 Capital Market Project Investment and Financing Compensation Survey - China | C21: SUBMISSIONCOMPANY | D21: 5 | E21: Participating Entity Annual Revenue Curr | F21: N | G21: NULL | H21: N | I21: 173 | J21: 172 | K21: 172 | L21: C | M21: CHAR | N21: ENTITY_REV_CURR | O21: DDE006 | P21: USE | Q21: L | R21: China | S21: CHN | T21: APC | U21: 12 | V21: 0 | W21: W | X21: Note: enter all financial data in whole numbers. | Y21: NULL | Z21: M | AA21: Y | AB21: Y | AC21: ~CORE~AERO_NA~SSO~RCE~AGRO_ZAF~MDSUK~YOUNGGRAD~MFG_LATAM~RENEWABLE~RENEWCLUB_FRA~AERO_EMEA~AERO_BRA~HC_GCC~HC_APAC~HIGHER_EDU~CMPIF_CHN~EDU_APAC~UPSTREAM_MYS~LEGAL_FEE_EARNERS~CL_PS_SUPPORTSTAFF_INTL~CL_HRG~DRILL_GLOBAL~DRILL_NAT_INTL~DRILL_NAT_NA~PSAR~INT~ | AD21: Participating Entity Annual Revenue Curr | AE21: Participating Entity Annual Revenue Currency | AF21: Note: enter all financial data in whole numbers. | AG21: NULL | AH21: NULL | AJ21: NULL
A22: A24149240511 | B22: 2025 Capital Market Project Investment and Financing Compensation Survey - China | C22: SUBMISSIONCONTACT | D22: 5 | E22: Long-Term Incentive Plans Contact Name | F22: N | G22: Mr. Joe Brady | H22: Y | I22: 986 | J22: NULL | K22: NULL | L22: NULL | M22: CHAR | N22: LTI_CONTACT_NAME | O22: DDE030 | P22: USE | Q22: L | R22: China | S22: CHN | T22: APC | U22: 250 | V22: 0 | W22: W | Y22: NULL | Z22: M | AA22: Y | AB22: Y | AC22: ~CORE~AERO_NA~SSO~RCE~AGRO_ZAF~MDSUK~MFG_LATAM~RENEWABLE~RENEWCLUB_FRA~AERO_EMEA~AERO_BRA~HC_GCC~HC_APAC~HIGHER_EDU~CMPIF_CHN~EDU_APAC~UPSTREAM_MYS~DRILL_GLOBAL~DRILL_NAT~CL_PS_SUPPORTSTAFF_INTL~CL_HRG~INT~ | AD22: Long-Term Incentive Plans Contact Name | AE22: Long-Term Incentive Plans Contact Name | AG22: Mr. Joe Brady | AH22: NULL | AJ22: NULL
